<?xml version='1.0' encoding='utf-8'?>
<robot name="box_02">
  <link name="l_0">
    <visual>
      <origin xyz="0 0 0" rpy="0 0 0" />
      <geometry>
        <mesh filename="./box_02_objs/0/0.obj" />
      </geometry>
    </visual>
    <collision>
      <origin xyz="0 0 0" rpy="0 0 0" />
      <geometry>
        <mesh filename="./box_02_objs/0/0.obj" />
      </geometry>
    </collision>
  </link>
  <link name="l_1">
    <visual>
      <origin xyz="0.0025000000000000044 -0.19750000000000006 0.0625" rpy="0 0 0" />
      <geometry>
        <mesh filename="./box_02_objs/1/1.obj" />
      </geometry>
    </visual>
    <collision>
      <origin xyz="0.0025000000000000044 -0.19750000000000006 0.0625" rpy="0 0 0" />
      <geometry>
        <mesh filename="./box_02_objs/1/1.obj" />
      </geometry>
    </collision>
  </link>
  <joint name="j_1" type="revolute">
    <parent link="l_0" />
    <child link="l_1" />
    <origin xyz="-0.0025000000000000044 0.19750000000000006 -0.0625" rpy="0 0 0" />
    <axis xyz="1.0 0.0 0.0" />
    <limit lower="-1.9478" upper="1.1310" effort="10" velocity="10" />
  </joint>
</robot>