<?xml version='1.0' encoding='utf-8'?>
<robot name="fridge_00">
  <link name="l_0">
    <visual>
      <origin xyz="0 0 0" rpy="0 0 0" />
      <geometry>
        <mesh filename="./fridge_00_objs/0/0.obj" />
      </geometry>
    </visual>
    <collision>
      <origin xyz="0 0 0" rpy="0 0 0" />
      <geometry>
        <mesh filename="./fridge_00_objs/0/0.obj" />
      </geometry>
    </collision>
  </link>
  <link name="l_1">
    <visual>
      <origin xyz="-0.22249999999999998 0.07250000000000001 0.0025000000000000044" rpy="0 0 0" />
      <geometry>
        <mesh filename="./fridge_00_objs/1/1.obj" />
      </geometry>
    </visual>
    <collision>
      <origin xyz="-0.22249999999999998 0.07250000000000001 0.0025000000000000044" rpy="0 0 0" />
      <geometry>
        <mesh filename="./fridge_00_objs/1/1.obj" />
      </geometry>
    </collision>
  </link>
  <link name="l_2">
    <visual>
      <origin xyz="0.2375 0.07250000000000001 0.0025000000000000044" rpy="0 0 0" />
      <geometry>
        <mesh filename="./fridge_00_objs/2/2.obj" />
      </geometry>
    </visual>
    <collision>
      <origin xyz="0.2375 0.07250000000000001 0.0025000000000000044" rpy="0 0 0" />
      <geometry>
        <mesh filename="./fridge_00_objs/2/2.obj" />
      </geometry>
    </collision>
  </link>
  <joint name="j_1" type="revolute">
    <parent link="l_0" />
    <child link="l_1" />
    <origin xyz="0.22249999999999998 -0.07250000000000001 -0.0025000000000000044" rpy="0 0 0" />
    <axis xyz="0.0 0.0 1.0" />
    <limit lower="-2.1363" upper="0.7540" effort="10" velocity="10" />
  </joint>
  <joint name="j_2" type="revolute">
    <parent link="l_0" />
    <child link="l_2" />
    <origin xyz="-0.2375 -0.07250000000000001 -0.0025000000000000044" rpy="0 0 0" />
    <axis xyz="0.0 0.0 1.0" />
    <limit lower="-0.8168" upper="2.0735" effort="10" velocity="10" />
  </joint>
</robot>