<?xml version='1.0' encoding='utf-8'?>
<robot name="laptop_00">
  <link name="l_0">
    <visual>
      <origin xyz="0 0 0" rpy="0 0 0" />
      <geometry>
        <mesh filename="./laptop_00_objs/0/0.obj" />
      </geometry>
    </visual>
    <collision>
      <origin xyz="0 0 0" rpy="0 0 0" />
      <geometry>
        <mesh filename="./laptop_00_objs/0/0.obj" />
      </geometry>
    </collision>
  </link>
  <link name="l_1">
    <visual>
      <origin xyz="0.0025000000000000044 -0.29250000000000004 0.32749999999999996" rpy="0 0 0" />
      <geometry>
        <mesh filename="./laptop_00_objs/1/1.obj" />
      </geometry>
    </visual>
    <collision>
      <origin xyz="0.0025000000000000044 -0.29250000000000004 0.32749999999999996" rpy="0 0 0" />
      <geometry>
        <mesh filename="./laptop_00_objs/1/1.obj" />
      </geometry>
    </collision>
  </link>
  <joint name="j_1" type="revolute">
    <parent link="l_0" />
    <child link="l_1" />
    <origin xyz="-0.0025000000000000044 0.29250000000000004 -0.32749999999999996" rpy="0 0 0" />
    <axis xyz="1.0 0.0 0.0" />
    <limit lower="-0.0628" upper="1.6965" effort="10" velocity="10" />
  </joint>
</robot>