<?xml version='1.0' encoding='utf-8'?>
<robot name="bottle_01">
  <link name="l_0">
    <visual>
      <origin xyz="0 0 0" rpy="0 0 0" />
      <geometry>
        <mesh filename="./bottle_01_objs/0/0.obj" />
      </geometry>
    </visual>
    <collision>
      <origin xyz="0 0 0" rpy="0 0 0" />
      <geometry>
        <mesh filename="./bottle_01_objs/0/0.obj" />
      </geometry>
    </collision>
  </link>
  <link name="l_1">
    <visual>
      <origin xyz="0.0025000000000000044 0.007500000000000008 0.0025000000000000044" rpy="0 0 0" />
      <geometry>
        <mesh filename="./bottle_01_objs/1/1.obj" />
      </geometry>
    </visual>
    <collision>
      <origin xyz="0.0025000000000000044 0.007500000000000008 0.0025000000000000044" rpy="0 0 0" />
      <geometry>
        <mesh filename="./bottle_01_objs/1/1.obj" />
      </geometry>
    </collision>
  </link>
  <joint name="j_1" type="revolute">
    <parent link="l_0" />
    <child link="l_1" />
    <origin xyz="-0.0025000000000000044 -0.007500000000000008 -0.0025000000000000044" rpy="0 0 0" />
    <axis xyz="0.0 0.0 1.0" />
    <limit lower="-3.1416" upper="3.1416" effort="10" velocity="10" />
  </joint>
</robot>